Workbook

Sheet 架電リスト
A1: 私立高等学校 架電リスト（北海道・東北・関東・中部22都道県／803校）
A2: 出典：学校ネット 私立高校検索結果（ご提供の貼り付けデータ）。電話番号は2026年10月にWeb検索で調査（確度はF列、出典はN列）。架電前に「確度：中・低」の番号は念のためご確認ください。
A4: No. | B4: 都道府県 | C4: 所在地（市区町村） | D4: 学校名 | E4: 電話番号 | F4: 番号の確度 | G4: 学科 | H4: 架電日 | I4: 担当者 | J4: 架電結果 | K4: 次回連絡日 | L4: メモ | M4: 電話番号の補足 | N4: 電話番号の出典 | O4: 学校情報ページ
A5: 1 | B5: 北海道 | C5: 旭川市 | D5: 旭川志峯高等学校 | E5: 0166-48-1221 | F5: 高 | G5: 普通科 | J5: 未架電 | M5: 旧称は旭川大学高校。ハローワーク旭川の名簿（R7.6）とJS日本の学校の番号が一致 | N5: https://jsite.mhlw.go.jp/hokkaido-hellowork/content/contents/002280302.pdf ; https://school.js88.com/scl_h/22052950 | O5: 開く
A6: 2 | B6: 北海道 | C6: 旭川市 | D6: 旭川実業高等学校 | E6: 0166-51-1246 | F6: 高 | G6: 普通科・専門学科 | J6: 未架電 | M6: ハローワーク名簿とJS日本の学校・みんなの高校情報の番号が一致 | N6: https://jsite.mhlw.go.jp/hokkaido-hellowork/content/contents/002280302.pdf ; https://school.js88.com/scl_h/22052940 | O6: 開く
A7: 3 | B7: 北海道 | C7: 旭川市 | D7: 旭川藤星高等学校 | E7: 0166-51-8125 | F7: 中 | G7: 普通科 | J7: 未架電 | M7: JS日本の学校のみで確認。公式サイトは asahikawa-tosei.jp | N7: https://school.js88.com/scl_h/22052920 | O7: 開く
A8: 4 | B8: 北海道 | C8: 旭川市 | D8: 旭川明成高等学校 | E8: 0166-51-3220 | F8: 高 | G8: 総合学科 | J8: 未架電 | M8: ハローワーク名簿とJS日本の学校の番号が一致 | N8: https://jsite.mhlw.go.jp/hokkaido-hellowork/content/contents/002280302.pdf ; https://school.js88.com/scl_h/22053120 | O8: 開く
A9: 5 | B9: 北海道 | C9: 旭川市 | D9: 旭川龍谷高等学校 | E9: 0166-39-2700 | F9: 高 | G9: 普通科 | J9: 未架電 | M9: JS日本の学校と道私学協会の資料（2023）の番号が一致 | N9: https://school.js88.com/scl_h/22052930 ; https://www.doshigaku.jp/pdf/2023_transfe_10.pdf | O9: 開く
A10: 6 | B10: 北海道 | C10: 函館市 | D10: 遺愛女子高等学校（青山学院大学教育提携校） | E10: 0138-51-0418 | F10: 高 | G10: 普通科・専門学科 | J10: 未架電 | M10: 公式パンフレットで確認。学院の代表番号（中学校と共通） | N10: https://www.iaijoshi-h.ed.jp/wp-content/uploads/2022/07/2023遺愛女子高校パンフレット.pdf | O10: 開く
A11: 7 | B11: 北海道 | C11: 札幌市豊平区 | D11: 池上学院高等学校 | E11: 011-811-5297 | F11: 中 | G11: 普通科 | J11: 未架電 | M11: 通信制・札幌本校の番号。入学相談用フリーダイヤル0120-195-315の記載もあり | N11: https://www.minkou.jp/hischool/school/330/ | O11: 開く
A12: 8 | B12: 北海道 | C12: 小樽市 | D12: 小樽双葉高等学校 | E12: 0134-32-1828 | F12: 高 | G12: 普通科 | J12: 未架電 | M12: JS日本の学校と道私学協会の資料の番号が一致。通信制課程の職員室は0134-31-3100 | N12: https://school.js88.com/scl_h/22052880 ; https://www.doshigaku.jp/pdf/2023_transfe_10.pdf | O12: 開く
A13: 9 | B13: 北海道 | C13: 小樽市 | D13: 小樽明峰高等学校 | E13: 0134-22-7755 | F13: 高 | G13: 普通科 | J13: 未架電 | M13: JS日本の学校と札幌市中学校の資料の番号が一致 | N13: https://school.js88.com/scl_h/22052890/ ; https://www16.sapporo-c.ed.jp/sakaeminami-j/attach/get2/4692/0 | O13: 開く
A14: 10 | B14: 北海道 | C14: 帯広市 | D14: 帯広大谷高等学校 | E14: 0155-33-5811 | F14: 中 | G14: 普通科 | J14: 未架電 | M14: 2018年の高文連資料のみで確認。最新かは未確認 | N14: https://www.koubunren-volunteer.hokkaido-c.ed.jp/wysiwyg/file/download/1/16 | O14: 開く
A15: 11 | B15: 北海道 | C15: 帯広市 | D15: 帯広北高等学校 | E15: 0155-47-0121 | F15: 高 | G15: 普通科 | J15: 未架電 | M15: JS日本の学校とみんなの高校情報の番号が一致 | N15: https://school.js88.com/scl_h/22053070 ; https://www.minkou.jp/hischool/school/1042/ | O15: 開く
A16: 12 | B16: 北海道 | C16: 室蘭市 | D16: 海星学院高等学校 | E16: 0143-46-8888 | F16: 中 | G16: 普通科 | J16: 未架電 | M16: JS日本の学校のみで確認 | N16: https://school.js88.com/scl_h/22053040 | O16: 開く
... A22: 18 | B22: 北海道 | C22: 札幌市南区 | D22: 札幌新陽高等学校 | E22: 011-821-6161 | F22: 高 | G22: 普通科 | J22: 未架電 | M22: 札幌市の一覧とJS日本の学校で一致 | N22: https://www.city.sapporo.jp/minami/shisetsu/sonota.html ; https://school.js88.com/scl_h/22052720 | O22: 開く
A23: 19 | B23: 北海道 | C23: 和寒町 | D23: 札幌自由が丘学園三和高等学校 | F23: 要調査 | G23: 普通科 | J23: 未架電 | M23: 和寒本校の番号を特定できず。候補：011-792-1468（公式では札幌学習センター）／011-743-1267。校名変更の可能性あり | N23: https://sanwa71.sakura.ne.jp/contact/ ; https://www.mapion.co.jp/phonebook/M11004/01464/ILSP0000041214_ipclm/ | O23: 開く
A24: 20 | B24: 北海道 | C24: 札幌市中央区 | D24: 札幌静修高等学校 | E24: 011-521-0234 | F24: 中 | G24: 普通科・専門学科 | J24: 未架電 | M24: JS日本の学校のみで確認 | N24: https://school.js88.com/scl_h/22052690 | O24: 開く
A25: 21 | B25: 北海道 | C25: 札幌市北区 | D25: 札幌創成高等学校 | E25: 011-726-1578 | F25: 高 | G25: 普通科 | J25: 未架電 | M25: 道私学協会の資料と札幌市中学校の配布資料で一致 | N25: https://www.doshigaku.jp/pdf/2023_transfe_10.pdf ; https://school.js88.com/scl_h/22049910 | O25: 開く
A26: 22 | B26: 北海道 | C26: 札幌市豊平区 | D26: 札幌第一高等学校 | E26: 011-851-9361 | F26: 高 | G26: 普通科 | J26: 未架電 | M26: 公式サイトで「代表」と確認。入試事務局は011-851-6729 | N26: https://www.kibou.ac.jp/daiichi/introduction/access/ | O26: 開く
A27: 23 | B27: 北海道 | C27: 北広島市 | D27: 札幌日本大学高等学校 | E27: 011-375-2611 | F27: 高 | G27: 普通科 | J27: 未架電 | M27: 複数資料で一致。中高併設 | N27: https://school.js88.com/scl_h/22053100 | O27: 開く
A28: 24 | B28: 北海道 | C28: 札幌市東区 | D28: 札幌北斗高等学校 | E28: 011-711-6121 | F28: 高 | G28: 普通科 | J28: 未架電 | M28: 札幌市東区の学校一覧と地図サイトで一致 | N28: https://www.city.sapporo.jp/higashi/about/ins_school.html | O28: 開く
A29: 25 | B29: 北海道 | C29: 札幌市西区 | D29: 札幌山の手高等学校 | E29: 011-611-7301 | F29: 高 | G29: 普通科 | J29: 未架電 | M29: 代表番号。札幌市立中学校の配布資料と一致 | N29: https://school.js88.com/scl_h/22052710 | O29: 開く
A30: 26 | B30: 北海道 | C30: 札幌市中央区 | D30: 札幌龍谷学園高等学校 | E30: 011-631-4386 | F30: 中 | G30: 普通科 | J30: 未架電 | M30: 札幌市立中学校の配布チラシで確認。公式サイトでは未確認 | N30: https://www16.sapporo-c.ed.jp/kiyota-j/attach/get2/2208/0 | O30: 開く
A31: 27 | B31: 北海道 | C31: 芽室町 | D31: 白樺学園高等学校 | E31: 0155-62-7411 | F31: 高 | G31: 普通科 | J31: 未架電 | M31: 中高併設 | N31: https://school.js88.com/scl_h/22053060 | O31: 開く
A32: 28 | B32: 北海道 | C32: 芦別市 | D32: 星槎国際高等学校 | E32: 0124-24-6101 | F32: 高 | G32: 普通科 | J32: 未架電 | M32: 芦別の本部校の番号（公式サイト）。全国にキャンパスあり | N32: https://seisa.ed.jp/ashibetsu/access/ | O32: 開く
A33: 29 | B33: 北海道 | C33: 函館市 | D33: 清尚学院高等学校 | E33: 0138-41-6584 | F33: 中 | G33: 専門学科 | J33: 未架電 | M33: JS日本の学校のみで確認 | N33: https://school.js88.com/scl_h/22052840 | O33: 開く
A34: 30 | B34: 北海道 | C34: 札幌市南区 | D34: 東海大学付属札幌高等学校 | E34: 011-571-5175 | F34: 高 | G34: 普通科 | J34: 未架電 | M34: 複数資料で一致 | N34: https://school.js88.com/scl_h/22052760/ | O34: 開く
A35: 31 | B35: 北海道 | C35: 苫小牧市 | D35: 苫小牧中央高等学校 | E35: 0144-74-4200 | F35: 高 | G35: 普通科 | J35: 未架電 | M35: 公式サイト：事務室。職員室は0144-74-4300 | N35: https://haragakuen.ac.jp/access/ | O35: 開く
... A224: 220 | B224: 埼玉県 | C224: 入間市 | D224: 狭山ヶ丘高等学校 | E224: 04-2962-3844 | F224: 高 | G224: 普通科 | J224: 未架電 | M224: 付属中学校と共通 | N224: https://www.inter-edu.com/schools/school/275 ; https://www.univpress.co.jp/gk_pdf/11514.pdf | O224: 開く
A225: 221 | B225: 埼玉県 | C225: 杉戸町 | D225: 志学会高等学校 | F225: 要調査 | G225: 普通科 | J225: 未架電 | M225: 通信制。電話番号が見つからず（杉戸町並塚。2025年8月に岩槻校舎開校） | N225: https://www.inter-edu.com/schools/school/1784 ; https://studychain.jp/media/guide-136-2/ | O225: 開く
A226: 222 | B226: 埼玉県 | C226: 上尾市 | D226: 秀明英光高等学校 | E226: 048-781-8821 | F226: 高 | G226: 普通科 | J226: 未架電 | M226: 公式パンフレットに「代表」と記載 | N226: https://www.shumei-eiko.ac.jp/cms/wp-content/uploads/2024/05/schoolguide2025.pdf | O226: 開く
A227: 223 | B227: 埼玉県 | C227: 川越市 | D227: 秀明高等学校 | E227: 049-232-6611 | F227: 中 | G227: 普通科 | J227: 未架電 | M227: 中高共通。学校情報サイト1件のみで確認 | N227: https://www.inter-edu.com/schools/school/1365 | O227: 開く
A228: 224 | B228: 埼玉県 | C228: さいたま市中央区 | D228: 淑徳与野高等学校 | E228: 048-840-1035 | F228: 高 | G228: 普通科 | J228: 未架電 | M228: 中高共通 | N228: https://www.inter-edu.com/schools/school/1933 | O228: 開く
A229: 225 | B229: 埼玉県 | C229: 川越市 | D229: 城西大学付属川越高等学校 | E229: 049-224-5665 | F229: 高 | G229: 普通科 | J229: 未架電 | M229: 中高共通。2つの情報源で一致 | N229: https://www.univpress.co.jp/gk_pdf/11526.pdf ; https://map.yahoo.co.jp/v3/place/7eCemCgbEls | O229: 開く
A230: 226 | B230: 埼玉県 | C230: 深谷市 | D230: 正智深谷高等学校 | E230: 048-571-6032 | F230: 中 | G230: 普通科 | J230: 未架電 | M230: 学校情報サイト1件のみで確認 | N230: https://www.inter-edu.com/schools/school/614 | O230: 開く
A231: 227 | B231: 埼玉県 | C231: 杉戸町 | D231: 昌平高等学校 | E231: 0480-34-3381 | F231: 高 | G231: 普通科 | J231: 未架電 | M231: 2つのサイトで一致 | N231: https://www.inter-edu.com/schools/school/267 ; https://school.js88.com/scl_h/22004930 | O231: 開く
A232: 228 | B232: 埼玉県 | C232: 飯能市 | D232: 自由の森学園高等学校 | E232: 042-972-3131 | F232: 高 | G232: 普通科 | J232: 未架電 | M232: 中高共通 | N232: https://www.inter-edu.com/schools/school/293 ; https://map.yahoo.co.jp/v3/place/L57Rs8n2arw | O232: 開く
A233: 229 | B233: 埼玉県 | C233: 川越市 | D233: 城北埼玉高等学校 | E233: 049-235-3222 | F233: 中 | G233: 普通科 | J233: 未架電 | M233: 中高併設。学校情報サイト1件のみで確認 | N233: https://www.inter-edu.com/schools/school/202 | O233: 開く
A234: 230 | B234: 埼玉県 | C234: 狭山市 | D234: 西武学園文理高等学校 | E234: 04-2954-4080 | F234: 高 | G234: 普通科・専門学科 | J234: 未架電 | M234: 公式資料に「代表」と記載。中高共通 | N234: https://www.bunri-s.ed.jp/wp-content/uploads/2023/09/8dc6f2ecb08556dbce1a5e6fdde67118.pdf | O234: 開く
...

Sheet 都道府県別集計
A1: 都道府県別 進捗集計（架電リストの入力に連動して自動計算）
A3: 都道府県 | B3: 学校数 | C3: 電話番号入力済 | D3: 架電済 | E3: 不在・折返し待ち | F3: 担当者不在 | G3: 資料送付 | H3: アポ獲得 | I3: 検討中 | J3: NG | K3: 番号不明
A4: 北海道 | B4: =COUNTIF('架電リスト'!$B$5:$B$807,A4) | C4: =COUNTIFS('架電リスト'!$B$5:$B$807,A4,'架電リスト'!$E$5:$E$807,"<>") | D4: =B4-COUNTIFS('架電リスト'!$B$5:$B$807,A4,'架電リスト'!$J$5:$J$807,"未架電")-COUNTIFS('架電リスト'!$B$5:$B$807,A4,'架電リスト'!$J$5:$J$807,"") | E4: =COUNTIFS('架電リスト'!$B$5:$B$807,$A4,'架電リスト'!$J$5:$J$807,"不在・折返し待ち") | F4: =COUNTIFS('架電リスト'!$B$5:$B$807,$A4,'架電リスト'!$J$5:$J$807,"担当者不在") | G4: =COUNTIFS('架電リスト'!$B$5:$B$807,$A4,'架電リスト'!$J$5:$J$807,"資料送付") | H4: =COUNTIFS('架電リスト'!$B$5:$B$807,$A4,'架電リスト'!$J$5:$J$807,"アポ獲得") | I4: =COUNTIFS('架電リスト'!$B$5:$B$807,$A4,'架電リスト'!$J$5:$J$807,"検討中") | J4: =COUNTIFS('架電リスト'!$B$5:$B$807,$A4,'架電リスト'!$J$5:$J$807,"NG") | K4: =COUNTIFS('架電リスト'!$B$5:$B$807,$A4,'架電リスト'!$J$5:$J$807,"番号不明")
A5: 青森県 | B5: =COUNTIF('架電リスト'!$B$5:$B$807,A5) | C5: =COUNTIFS('架電リスト'!$B$5:$B$807,A5,'架電リスト'!$E$5:$E$807,"<>") | D5: =B5-COUNTIFS('架電リスト'!$B$5:$B$807,A5,'架電リスト'!$J$5:$J$807,"未架電")-COUNTIFS('架電リスト'!$B$5:$B$807,A5,'架電リスト'!$J$5:$J$807,"") | E5: =COUNTIFS('架電リスト'!$B$5:$B$807,$A5,'架電リスト'!$J$5:$J$807,"不在・折返し待ち") | F5: =COUNTIFS('架電リスト'!$B$5:$B$807,$A5,'架電リスト'!$J$5:$J$807,"担当者不在") | G5: =COUNTIFS('架電リスト'!$B$5:$B$807,$A5,'架電リスト'!$J$5:$J$807,"資料送付") | H5: =COUNTIFS('架電リスト'!$B$5:$B$807,$A5,'架電リスト'!$J$5:$J$807,"アポ獲得") | I5: =COUNTIFS('架電リスト'!$B$5:$B$807,$A5,'架電リスト'!$J$5:$J$807,"検討中") | J5: =COUNTIFS('架電リスト'!$B$5:$B$807,$A5,'架電リスト'!$J$5:$J$807,"NG") | K5: =COUNTIFS('架電リスト'!$B$5:$B$807,$A5,'架電リスト'!$J$5:$J$807,"番号不明")
A6: 岩手県 | B6: =COUNTIF('架電リスト'!$B$5:$B$807,A6) | C6: =COUNTIFS('架電リスト'!$B$5:$B$807,A6,'架電リスト'!$E$5:$E$807,"<>") | D6: =B6-COUNTIFS('架電リスト'!$B$5:$B$807,A6,'架電リスト'!$J$5:$J$807,"未架電")-COUNTIFS('架電リスト'!$B$5:$B$807,A6,'架電リスト'!$J$5:$J$807,"") | E6: =COUNTIFS('架電リスト'!$B$5:$B$807,$A6,'架電リスト'!$J$5:$J$807,"不在・折返し待ち") | F6: =COUNTIFS('架電リスト'!$B$5:$B$807,$A6,'架電リスト'!$J$5:$J$807,"担当者不在") | G6: =COUNTIFS('架電リスト'!$B$5:$B$807,$A6,'架電リスト'!$J$5:$J$807,"資料送付") | H6: =COUNTIFS('架電リスト'!$B$5:$B$807,$A6,'架電リスト'!$J$5:$J$807,"アポ獲得") | I6: =COUNTIFS('架電リスト'!$B$5:$B$807,$A6,'架電リスト'!$J$5:$J$807,"検討中") | J6: =COUNTIFS('架電リスト'!$B$5:$B$807,$A6,'架電リスト'!$J$5:$J$807,"NG") | K6: =COUNTIFS('架電リスト'!$B$5:$B$807,$A6,'架電リスト'!$J$5:$J$807,"番号不明")
A7: 宮城県 | B7: =COUNTIF('架電リスト'!$B$5:$B$807,A7) | C7: =COUNTIFS('架電リスト'!$B$5:$B$807,A7,'架電リスト'!$E$5:$E$807,"<>") | D7: =B7-COUNTIFS('架電リスト'!$B$5:$B$807,A7,'架電リスト'!$J$5:$J$807,"未架電")-COUNTIFS('架電リスト'!$B$5:$B$807,A7,'架電リスト'!$J$5:$J$807,"") | E7: =COUNTIFS('架電リスト'!$B$5:$B$807,$A7,'架電リスト'!$J$5:$J$807,"不在・折返し待ち") | F7: =COUNTIFS('架電リスト'!$B$5:$B$807,$A7,'架電リスト'!$J$5:$J$807,"担当者不在") | G7: =COUNTIFS('架電リスト'!$B$5:$B$807,$A7,'架電リスト'!$J$5:$J$807,"資料送付") | H7: =COUNTIFS('架電リスト'!$B$5:$B$807,$A7,'架電リスト'!$J$5:$J$807,"アポ獲得") | I7: =COUNTIFS('架電リスト'!$B$5:$B$807,$A7,'架電リスト'!$J$5:$J$807,"検討中") | J7: =COUNTIFS('架電リスト'!$B$5:$B$807,$A7,'架電リスト'!$J$5:$J$807,"NG") | K7: =COUNTIFS('架電リスト'!$B$5:$B$807,$A7,'架電リスト'!$J$5:$J$807,"番号不明")
A8: 秋田県 | B8: =COUNTIF('架電リスト'!$B$5:$B$807,A8) | C8: =COUNTIFS('架電リスト'!$B$5:$B$807,A8,'架電リスト'!$E$5:$E$807,"<>") | D8: =B8-COUNTIFS('架電リスト'!$B$5:$B$807,A8,'架電リスト'!$J$5:$J$807,"未架電")-COUNTIFS('架電リスト'!$B$5:$B$807,A8,'架電リスト'!$J$5:$J$807,"") | E8: =COUNTIFS('架電リスト'!$B$5:$B$807,$A8,'架電リスト'!$J$5:$J$807,"不在・折返し待ち") | F8: =COUNTIFS('架電リスト'!$B$5:$B$807,$A8,'架電リスト'!$J$5:$J$807,"担当者不在") | G8: =COUNTIFS('架電リスト'!$B$5:$B$807,$A8,'架電リスト'!$J$5:$J$807,"資料送付") | H8: =COUNTIFS('架電リスト'!$B$5:$B$807,$A8,'架電リスト'!$J$5:$J$807,"アポ獲得") | I8: =COUNTIFS('架電リスト'!$B$5:$B$807,$A8,'架電リスト'!$J$5:$J$807,"検討中") | J8: =COUNTIFS('架電リスト'!$B$5:$B$807,$A8,'架電リスト'!$J$5:$J$807,"NG") | K8: =COUNTIFS('架電リスト'!$B$5:$B$807,$A8,'架電リスト'!$J$5:$J$807,"番号不明")
A9: 山形県 | B9: =COUNTIF('架電リスト'!$B$5:$B$807,A9) | C9: =COUNTIFS('架電リスト'!$B$5:$B$807,A9,'架電リスト'!$E$5:$E$807,"<>") | D9: =B9-COUNTIFS('架電リスト'!$B$5:$B$807,A9,'架電リスト'!$J$5:$J$807,"未架電")-COUNTIFS('架電リスト'!$B$5:$B$807,A9,'架電リスト'!$J$5:$J$807,"") | E9: =COUNTIFS('架電リスト'!$B$5:$B$807,$A9,'架電リスト'!$J$5:$J$807,"不在・折返し待ち") | F9: =COUNTIFS('架電リスト'!$B$5:$B$807,$A9,'架電リスト'!$J$5:$J$807,"担当者不在") | G9: =COUNTIFS('架電リスト'!$B$5:$B$807,$A9,'架電リスト'!$J$5:$J$807,"資料送付") | H9: =COUNTIFS('架電リスト'!$B$5:$B$807,$A9,'架電リスト'!$J$5:$J$807,"アポ獲得") | I9: =COUNTIFS('架電リスト'!$B$5:$B$807,$A9,'架電リスト'!$J$5:$J$807,"検討中") | J9: =COUNTIFS('架電リスト'!$B$5:$B$807,$A9,'架電リスト'!$J$5:$J$807,"NG") | K9: =COUNTIFS('架電リスト'!$B$5:$B$807,$A9,'架電リスト'!$J$5:$J$807,"番号不明")
A10: 福島県 | B10: =COUNTIF('架電リスト'!$B$5:$B$807,A10) | C10: =COUNTIFS('架電リスト'!$B$5:$B$807,A10,'架電リスト'!$E$5:$E$807,"<>") | D10: =B10-COUNTIFS('架電リスト'!$B$5:$B$807,A10,'架電リスト'!$J$5:$J$807,"未架電")-COUNTIFS('架電リスト'!$B$5:$B$807,A10,'架電リスト'!$J$5:$J$807,"") | E10: =COUNTIFS('架電リスト'!$B$5:$B$807,$A10,'架電リスト'!$J$5:$J$807,"不在・折返し待ち") | F10: =COUNTIFS('架電リスト'!$B$5:$B$807,$A10,'架電リスト'!$J$5:$J$807,"担当者不在") | G10: =COUNTIFS('架電リスト'!$B$5:$B$807,$A10,'架電リスト'!$J$5:$J$807,"資料送付") | H10: =COUNTIFS('架電リスト'!$B$5:$B$807,$A10,'架電リスト'!$J$5:$J$807,"アポ獲得") | I10: =COUNTIFS('架電リスト'!$B$5:$B$807,$A10,'架電リスト'!$J$5:$J$807,"検討中") | J10: =COUNTIFS('架電リスト'!$B$5:$B$807,$A10,'架電リスト'!$J$5:$J$807,"NG") | K10: =COUNTIFS('架電リスト'!$B$5:$B$807,$A10,'架電リスト'!$J$5:$J$807,"番号不明")
A11: 茨城県 | B11: =COUNTIF('架電リスト'!$B$5:$B$807,A11) | C11: =COUNTIFS('架電リスト'!$B$5:$B$807,A11,'架電リスト'!$E$5:$E$807,"<>") | D11: =B11-COUNTIFS('架電リスト'!$B$5:$B$807,A11,'架電リスト'!$J$5:$J$807,"未架電")-COUNTIFS('架電リスト'!$B$5:$B$807,A11,'架電リスト'!$J$5:$J$807,"") | E11: =COUNTIFS('架電リスト'!$B$5:$B$807,$A11,'架電リスト'!$J$5:$J$807,"不在・折返し待ち") | F11: =COUNTIFS('架電リスト'!$B$5:$B$807,$A11,'架電リスト'!$J$5:$J$807,"担当者不在") | G11: =COUNTIFS('架電リスト'!$B$5:$B$807,$A11,'架電リスト'!$J$5:$J$807,"資料送付") | H11: =COUNTIFS('架電リスト'!$B$5:$B$807,$A11,'架電リスト'!$J$5:$J$807,"アポ獲得") | I11: =COUNTIFS('架電リスト'!$B$5:$B$807,$A11,'架電リスト'!$J$5:$J$807,"検討中") | J11: =COUNTIFS('架電リスト'!$B$5:$B$807,$A11,'架電リスト'!$J$5:$J$807,"NG") | K11: =COUNTIFS('架電リスト'!$B$5:$B$807,$A11,'架電リスト'!$J$5:$J$807,"番号不明")
A12: 栃木県 | B12: =COUNTIF('架電リスト'!$B$5:$B$807,A12) | C12: =COUNTIFS('架電リスト'!$B$5:$B$807,A12,'架電リスト'!$E$5:$E$807,"<>") | D12: =B12-COUNTIFS('架電リスト'!$B$5:$B$807,A12,'架電リスト'!$J$5:$J$807,"未架電")-COUNTIFS('架電リスト'!$B$5:$B$807,A12,'架電リスト'!$J$5:$J$807,"") | E12: =COUNTIFS('架電リスト'!$B$5:$B$807,$A12,'架電リスト'!$J$5:$J$807,"不在・折返し待ち") | F12: =COUNTIFS('架電リスト'!$B$5:$B$807,$A12,'架電リスト'!$J$5:$J$807,"担当者不在") | G12: =COUNTIFS('架電リスト'!$B$5:$B$807,$A12,'架電リスト'!$J$5:$J$807,"資料送付") | H12: =COUNTIFS('架電リスト'!$B$5:$B$807,$A12,'架電リスト'!$J$5:$J$807,"アポ獲得") | I12: =COUNTIFS('架電リスト'!$B$5:$B$807,$A12,'架電リスト'!$J$5:$J$807,"検討中") | J12: =COUNTIFS('架電リスト'!$B$5:$B$807,$A12,'架電リスト'!$J$5:$J$807,"NG") | K12: =COUNTIFS('架電リスト'!$B$5:$B$807,$A12,'架電リスト'!$J$5:$J$807,"番号不明")
A13: 群馬県 | B13: =COUNTIF('架電リスト'!$B$5:$B$807,A13) | C13: =COUNTIFS('架電リスト'!$B$5:$B$807,A13,'架電リスト'!$E$5:$E$807,"<>") | D13: =B13-COUNTIFS('架電リスト'!$B$5:$B$807,A13,'架電リスト'!$J$5:$J$807,"未架電")-COUNTIFS('架電リスト'!$B$5:$B$807,A13,'架電リスト'!$J$5:$J$807,"") | E13: =COUNTIFS('架電リスト'!$B$5:$B$807,$A13,'架電リスト'!$J$5:$J$807,"不在・折返し待ち") | F13: =COUNTIFS('架電リスト'!$B$5:$B$807,$A13,'架電リスト'!$J$5:$J$807,"担当者不在") | G13: =COUNTIFS('架電リスト'!$B$5:$B$807,$A13,'架電リスト'!$J$5:$J$807,"資料送付") | H13: =COUNTIFS('架電リスト'!$B$5:$B$807,$A13,'架電リスト'!$J$5:$J$807,"アポ獲得") | I13: =COUNTIFS('架電リスト'!$B$5:$B$807,$A13,'架電リスト'!$J$5:$J$807,"検討中") | J13: =COUNTIFS('架電リスト'!$B$5:$B$807,$A13,'架電リスト'!$J$5:$J$807,"NG") | K13: =COUNTIFS('架電リスト'!$B$5:$B$807,$A13,'架電リスト'!$J$5:$J$807,"番号不明")
A14: 埼玉県 | B14: =COUNTIF('架電リスト'!$B$5:$B$807,A14) | C14: =COUNTIFS('架電リスト'!$B$5:$B$807,A14,'架電リスト'!$E$5:$E$807,"<>") | D14: =B14-COUNTIFS('架電リスト'!$B$5:$B$807,A14,'架電リスト'!$J$5:$J$807,"未架電")-COUNTIFS('架電リスト'!$B$5:$B$807,A14,'架電リスト'!$J$5:$J$807,"") | E14: =COUNTIFS('架電リスト'!$B$5:$B$807,$A14,'架電リスト'!$J$5:$J$807,"不在・折返し待ち") | F14: =COUNTIFS('架電リスト'!$B$5:$B$807,$A14,'架電リスト'!$J$5:$J$807,"担当者不在") | G14: =COUNTIFS('架電リスト'!$B$5:$B$807,$A14,'架電リスト'!$J$5:$J$807,"資料送付") | H14: =COUNTIFS('架電リスト'!$B$5:$B$807,$A14,'架電リスト'!$J$5:$J$807,"アポ獲得") | I14: =COUNTIFS('架電リスト'!$B$5:$B$807,$A14,'架電リスト'!$J$5:$J$807,"検討中") | J14: =COUNTIFS('架電リスト'!$B$5:$B$807,$A14,'架電リスト'!$J$5:$J$807,"NG") | K14: =COUNTIFS('架電リスト'!$B$5:$B$807,$A14,'架電リスト'!$J$5:$J$807,"番号不明")
A15: 千葉県 | B15: =COUNTIF('架電リスト'!$B$5:$B$807,A15) | C15: =COUNTIFS('架電リスト'!$B$5:$B$807,A15,'架電リスト'!$E$5:$E$807,"<>") | D15: =B15-COUNTIFS('架電リスト'!$B$5:$B$807,A15,'架電リスト'!$J$5:$J$807,"未架電")-COUNTIFS('架電リスト'!$B$5:$B$807,A15,'架電リスト'!$J$5:$J$807,"") | E15: =COUNTIFS('架電リスト'!$B$5:$B$807,$A15,'架電リスト'!$J$5:$J$807,"不在・折返し待ち") | F15: =COUNTIFS('架電リスト'!$B$5:$B$807,$A15,'架電リスト'!$J$5:$J$807,"担当者不在") | G15: =COUNTIFS('架電リスト'!$B$5:$B$807,$A15,'架電リスト'!$J$5:$J$807,"資料送付") | H15: =COUNTIFS('架電リスト'!$B$5:$B$807,$A15,'架電リスト'!$J$5:$J$807,"アポ獲得") | I15: =COUNTIFS('架電リスト'!$B$5:$B$807,$A15,'架電リスト'!$J$5:$J$807,"検討中") | J15: =COUNTIFS('架電リスト'!$B$5:$B$807,$A15,'架電リスト'!$J$5:$J$807,"NG") | K15: =COUNTIFS('架電リスト'!$B$5:$B$807,$A15,'架電リスト'!$J$5:$J$807,"番号不明")
... A25: 愛知県 | B25: =COUNTIF('架電リスト'!$B$5:$B$807,A25) | C25: =COUNTIFS('架電リスト'!$B$5:$B$807,A25,'架電リスト'!$E$5:$E$807,"<>") | D25: =B25-COUNTIFS('架電リスト'!$B$5:$B$807,A25,'架電リスト'!$J$5:$J$807,"未架電")-COUNTIFS('架電リスト'!$B$5:$B$807,A25,'架電リスト'!$J$5:$J$807,"") | E25: =COUNTIFS('架電リスト'!$B$5:$B$807,$A25,'架電リスト'!$J$5:$J$807,"不在・折返し待ち") | F25: =COUNTIFS('架電リスト'!$B$5:$B$807,$A25,'架電リスト'!$J$5:$J$807,"担当者不在") | G25: =COUNTIFS('架電リスト'!$B$5:$B$807,$A25,'架電リスト'!$J$5:$J$807,"資料送付") | H25: =COUNTIFS('架電リスト'!$B$5:$B$807,$A25,'架電リスト'!$J$5:$J$807,"アポ獲得") | I25: =COUNTIFS('架電リスト'!$B$5:$B$807,$A25,'架電リスト'!$J$5:$J$807,"検討中") | J25: =COUNTIFS('架電リスト'!$B$5:$B$807,$A25,'架電リスト'!$J$5:$J$807,"NG") | K25: =COUNTIFS('架電リスト'!$B$5:$B$807,$A25,'架電リスト'!$J$5:$J$807,"番号不明")
A26: 合計 | B26: =SUM(B4:B25) | C26: =SUM(C4:C25) | D26: =SUM(D4:D25) | E26: =SUM(E4:E25) | F26: =SUM(F4:F25) | G26: =SUM(G4:G25) | H26: =SUM(H4:H25) | I26: =SUM(I4:I25) | ... K26: =SUM(K4:K25)

Sheet 使い方・注意事項
A1: ■ 使い方
A2: ・「架電リスト」の黄色の列（電話番号・架電日・担当者・架電結果・次回連絡日・メモ）に入力してください。
A3: ・架電結果はプルダウンから選択します（アポ獲得＝緑、NG＝グレーで行が自動着色）。
A4: ・「学校情報ページ」の「開く」をクリックすると、学校ネットの各校ページが開きます。
A5: ・「番号の確度」：高＝公式サイト、または2つ以上の情報源で一致／中＝情報サイト1件のみ、または代表番号と断定できず（補足欄参照）／低・要調査＝特定できず。
A6: ・「電話番号の補足」に、代表番号の共有・別番号（入試事務局など）・移転などの注意を記載しています。架電前にご確認ください。
A7: ・都道府県や市区町村で絞り込む場合は、見出し行の▼（フィルター）を使用してください。
A8: ・集計シートは入力内容に連動して自動で集計されます。
A10: ■ 元データについての注意
A11: ・出典：ご提供いただいた学校ネットの検索結果（私立高校・北海道・東北・関東・中部22都道県、803校）の貼り付けデータ。並び順は都道府県ごとに元データの掲載順です。
A12: ・電話番号は元データに記載がないため、2026年10月にWeb検索（学校公式サイト、JS日本の学校、みんなの高校情報、自治体・ハローワーク・各道県の私学協会の資料など）で調査しました。推測による補完はしていません。
A13: ・通信制（広域通信制）の学校は、所在地・電話番号とも本校のものです。架電先（本校／各キャンパス）にご注意ください。
A14: ・閉校・統合・校名変更などは反映されていない可能性があります。架電前にご確認ください。
